[Wed Sep 18 00:18:33 2013] [error] [client 128.239.150.118] mod_wsgi (pid=21179, process='[HOST]', application='[HOST]|'): Failed to parse WSGI script file '/home/ubuntu/eeg/apache/django.wsgi'.
[Wed Sep 18 00:18:33 2013] [error] [client 128.239.150.118] mod_wsgi (pid=21179): Exception occurred processing WSGI script '/home/ubuntu/eeg/apache/django.wsgi'.
[Wed Sep 18 00:18:33 2013] [error] [client 128.239.150.118]   File "/home/ubuntu/eeg/apache/django.wsgi", line 4
[Wed Sep 18 00:18:33 2013] [error] [client 128.239.150.118] SyntaxError: Non-ASCII character '\\xe2' in file /home/ubuntu/eeg/apache/django.wsgi on line 4, but no encoding declared; see http://www.python.org/peps/pep-0263.html for details
[Wed Sep 18 00:20:35 2013] [error] [client 128.239.150.118] mod_wsgi (pid=21178, process='[HOST]', application='[HOST]|'): Failed to parse WSGI script file '/home/ubuntu/eeg/apache/django.wsgi'.
[Wed Sep 18 00:20:35 2013] [error] [client 128.239.150.118] mod_wsgi (pid=21178): Exception occurred processing WSGI script '/home/ubuntu/eeg/apache/django.wsgi'.
[Wed Sep 18 00:20:35 2013] [error] [client 128.239.150.118]   File "/home/ubuntu/eeg/apache/django.wsgi", line 4
[Wed Sep 18 00:20:35 2013] [error] [client 128.239.150.118] SyntaxError: Non-ASCII character '\\xe2' in file /home/ubuntu/eeg/apache/django.wsgi on line 4, but no encoding declared; see http://www.python.org/peps/pep-0263.html for details
[Wed Sep 18 00:21:29 2013] [error] [client 128.239.150.118] mod_wsgi (pid=21560, process='[HOST]', application='[HOST]|'): Failed to parse WSGI script file '/home/ubuntu/eeg/apache/django.wsgi'.
[Wed Sep 18 00:21:29 2013] [error] [client 128.239.150.118] mod_wsgi (pid=21560): Exception occurred processing WSGI script '/home/ubuntu/eeg/apache/django.wsgi'.
[Wed Sep 18 00:21:29 2013] [error] [client 128.239.150.118]   File "/home/ubuntu/eeg/apache/django.wsgi", line 4
[Wed Sep 18 00:21:29 2013] [error] [client 128.239.150.118] SyntaxError: Non-ASCII character '\\xe2' in file /home/ubuntu/eeg/apache/django.wsgi on line 4, but no encoding declared; see http://www.python.org/peps/pep-0263.html for details
[Wed Sep 18 00:21:45 2013] [error] [client 128.239.150.118] mod_wsgi (pid=21857, process='[HOST]', application='[HOST]|'): Failed to parse WSGI script file '/home/ubuntu/eeg/apache/django.wsgi'.
[Wed Sep 18 00:21:45 2013] [error] [client 128.239.150.118] mod_wsgi (pid=21857): Exception occurred processing WSGI script '/home/ubuntu/eeg/apache/django.wsgi'.
[Wed Sep 18 00:21:45 2013] [error] [client 128.239.150.118]   File "/home/ubuntu/eeg/apache/django.wsgi", line 4
[Wed Sep 18 00:21:45 2013] [error] [client 128.239.150.118] SyntaxError: Non-ASCII character '\\xe2' in file /home/ubuntu/eeg/apache/django.wsgi on line 4, but no encoding declared; see http://www.python.org/peps/pep-0263.html for details
[Wed Sep 18 00:21:55 2013] [error] [client 128.239.150.118] mod_wsgi (pid=21856, process='[HOST]', application='[HOST]|'): Failed to parse WSGI script file '/home/ubuntu/eeg/apache/django.wsgi'.
[Wed Sep 18 00:21:55 2013] [error] [client 128.239.150.118] mod_wsgi (pid=21856): Exception occurred processing WSGI script '/home/ubuntu/eeg/apache/django.wsgi'.
[Wed Sep 18 00:21:55 2013] [error] [client 128.239.150.118]   File "/home/ubuntu/eeg/apache/django.wsgi", line 4
[Wed Sep 18 00:21:55 2013] [error] [client 128.239.150.118] SyntaxError: Non-ASCII character '\\xe2' in file /home/ubuntu/eeg/apache/django.wsgi on line 4, but no encoding declared; see http://www.python.org/peps/pep-0263.html for details
[Wed Sep 18 00:26:21 2013] [error] [client 128.239.150.118] mod_wsgi (pid=22178, process='[HOST]', application='[HOST]|'): Failed to parse WSGI script file '/home/ubuntu/eeg/apache/django.wsgi'.
[Wed Sep 18 00:26:21 2013] [error] [client 128.239.150.118] mod_wsgi (pid=22178): Exception occurred processing WSGI script '/home/ubuntu/eeg/apache/django.wsgi'.
[Wed Sep 18 00:26:21 2013] [error] [client 128.239.150.118]   File "/home/ubuntu/eeg/apache/django.wsgi", line 4
[Wed Sep 18 00:26:21 2013] [error] [client 128.239.150.118] SyntaxError: Non-ASCII character '\\xe2' in file /home/ubuntu/eeg/apache/django.wsgi on line 4, but no encoding declared; see http://www.python.org/peps/pep-0263.html for details
[Wed Sep 18 00:26:23 2013] [error] [client 128.239.150.118] mod_wsgi (pid=22177, process='[HOST]', application='[HOST]|'): Failed to parse WSGI script file '/home/ubuntu/eeg/apache/django.wsgi'.
[Wed Sep 18 00:26:23 2013] [error] [client 128.239.150.118] mod_wsgi (pid=22177): Exception occurred processing WSGI script '/home/ubuntu/eeg/apache/django.wsgi'.
[Wed Sep 18 00:26:23 2013] [error] [client 128.239.150.118]   File "/home/ubuntu/eeg/apache/django.wsgi", line 4
[Wed Sep 18 00:26:23 2013] [error] [client 128.239.150.118] SyntaxError: Non-ASCII character '\\xe2' in file /home/ubuntu/eeg/apache/django.wsgi on line 4, but no encoding declared; see http://www.python.org/peps/pep-0263.html for details
[Wed Sep 18 00:26:39 2013] [error] [client 128.239.150.118] mod_wsgi (pid=22470, process='[HOST]', application='[HOST]|'): Failed to parse WSGI script file '/home/ubuntu/eeg/apache/django.wsgi'.
[Wed Sep 18 00:26:39 2013] [error] [client 128.239.150.118] mod_wsgi (pid=22470): Exception occurred processing WSGI script '/home/ubuntu/eeg/apache/django.wsgi'.
[Wed Sep 18 00:26:39 2013] [error] [client 128.239.150.118]   File "/home/ubuntu/eeg/apache/django.wsgi", line 4
[Wed Sep 18 00:26:39 2013] [error] [client 128.239.150.118] SyntaxError: Non-ASCII character '\\xe2' in file /home/ubuntu/eeg/apache/django.wsgi on line 4, but no encoding declared; see http://www.python.org/peps/pep-0263.html for details
[Wed Sep 18 00:30:31 2013] [error] [client 128.239.150.118] mod_wsgi (pid=22696, process='[HOST]', application='[HOST]|'): Failed to parse WSGI script file '/home/ubuntu/eeg/apache/django.wsgi'.
[Wed Sep 18 00:30:31 2013] [error] [client 128.239.150.118] mod_wsgi (pid=22696): Exception occurred processing WSGI script '/home/ubuntu/eeg/apache/django.wsgi'.
[Wed Sep 18 00:30:31 2013] [error] [client 128.239.150.118]   File "/home/ubuntu/eeg/apache/django.wsgi", line 5
[Wed Sep 18 00:30:31 2013] [error] [client 128.239.150.118]     path = \xe2\x80\x98/home/ubuntu/eeg\xe2\x80\x98
[Wed Sep 18 00:30:31 2013] [error] [client 128.239.150.118]            ^
[Wed Sep 18 00:30:31 2013] [error] [client 128.239.150.118] SyntaxError: invalid syntax
[Wed Sep 18 00:30:46 2013] [error] [client 128.239.150.118] mod_wsgi (pid=22989, process='[HOST]', application='[HOST]|'): Failed to parse WSGI script file '/home/ubuntu/eeg/apache/django.wsgi'.
[Wed Sep 18 00:30:46 2013] [error] [client 128.239.150.118] mod_wsgi (pid=22989): Exception occurred processing WSGI script '/home/ubuntu/eeg/apache/django.wsgi'.
[Wed Sep 18 00:30:46 2013] [error] [client 128.239.150.118]   File "/home/ubuntu/eeg/apache/django.wsgi", line 5
[Wed Sep 18 00:30:46 2013] [error] [client 128.239.150.118]     path = \xe2\x80\x98/home/ubuntu/eeg\xe2\x80\x98
[Wed Sep 18 00:30:46 2013] [error] [client 128.239.150.118]            ^
[Wed Sep 18 00:30:46 2013] [error] [client 128.239.150.118] SyntaxError: invalid syntax
[Wed Sep 18 00:31:55 2013] [error] [client 128.239.150.118] mod_wsgi (pid=23229, process='[HOST]', application='[HOST]|'): Failed to parse WSGI script file '/home/ubuntu/eeg/apache/django.wsgi'.
[Wed Sep 18 00:31:55 2013] [error] [client 128.239.150.118] mod_wsgi (pid=23229): Exception occurred processing WSGI script '/home/ubuntu/eeg/apache/django.wsgi'.
[Wed Sep 18 00:31:55 2013] [error] [client 128.239.150.118]   File "/home/ubuntu/eeg/apache/django.wsgi", line 8
[Wed Sep 18 00:31:55 2013] [error] [client 128.239.150.118]     sys.path.append(path)
[Wed Sep 18 00:31:55 2013] [error] [client 128.239.150.118]       ^
[Wed Sep 18 00:31:55 2013] [error] [client 128.239.150.118] IndentationError: expected an indented block
[Wed Sep 18 00:33:29 2013] [error] [client 128.239.150.118] mod_wsgi (pid=23432, process='[HOST]', application='[HOST]|'): Failed to parse WSGI script file '/home/ubuntu/eeg/apache/django.wsgi'.
[Wed Sep 18 00:33:29 2013] [error] [client 128.239.150.118] mod_wsgi (pid=23432): Exception occurred processing WSGI script '/home/ubuntu/eeg/apache/django.wsgi'.
[Wed Sep 18 00:33:29 2013] [error] [client 128.239.150.118]   File "/home/ubuntu/eeg/apache/django.wsgi", line 10
[Wed Sep 18 00:33:29 2013] [error] [client 128.239.150.118]     os.environ['DJANGO_SETTINGS_MODULE'] = \xe2\x80\x98eeg.settings\xe2\x80\x99
[Wed Sep 18 00:33:29 2013] [error] [client 128.239.150.118]                                            ^
[Wed Sep 18 00:33:29 2013] [error] [client 128.239.150.118] SyntaxError: invalid syntax
[Wed Sep 18 23:55:53 2013] [error] Internal Server Error: /phppath/php
[Wed Sep 18 23:55:53 2013] [error] Traceback (most recent call last):
[Wed Sep 18 23:55:53 2013] [error]   File "/usr/local/lib/python2.7/dist-packages/django/core/handlers/base.py", line 92, in get_response
[Wed Sep 18 23:55:53 2013] [error]     response = middleware_method(request)
[Wed Sep 18 23:55:53 2013] [error]   File "/usr/local/lib/python2.7/dist-packages/django/middleware/common.py", line 57, in process_request
[Wed Sep 18 23:55:53 2013] [error]     host = request.get_host()
[Wed Sep 18 23:55:53 2013] [error]   File "/usr/local/lib/python2.7/dist-packages/django/http/request.py", line 72, in get_host
[Wed Sep 18 23:55:53 2013] [error]     "Invalid HTTP_HOST header (you may need to set ALLOWED_HOSTS): %s" % host)
[Wed Sep 18 23:55:53 2013] [error] SuspiciousOperation: Invalid HTTP_HOST header (you may need to set ALLOWED_HOSTS): [HOST]
[Wed Sep 18 23:55:53 2013] [error] [client 193.255.130.116] mod_wsgi (pid=23785): Exception occurred processing WSGI script '/home/ubuntu/eeg/apache/django.wsgi'.
[Wed Sep 18 23:55:53 2013] [error] [client 193.255.130.116] Traceback (most recent call last):
[Wed Sep 18 23:55:53 2013] [error] [client 193.255.130.116]   File "/usr/local/lib/python2.7/dist-packages/django/core/handlers/wsgi.py", line 255, in __call__
[Wed Sep 18 23:55:53 2013] [error] [client 193.255.130.116]     response = self.get_response(request)
[Wed Sep 18 23:55:53 2013] [error] [client 193.255.130.116]   File "/usr/local/lib/python2.7/dist-packages/django/core/handlers/base.py", line 178, in get_response
[Wed Sep 18 23:55:53 2013] [error] [client 193.255.130.116]     response = self.handle_uncaught_exception(request, resolver, sys.exc_info())
[Wed Sep 18 23:55:53 2013] [error] [client 193.255.130.116]   File "/usr/local/lib/python2.7/dist-packages/django/core/handlers/base.py", line 217, in handle_uncaught_exception
[Wed Sep 18 23:55:53 2013] [error] [client 193.255.130.116]     return debug.technical_500_response(request, *exc_info)
[Wed Sep 18 23:55:53 2013] [error] [client 193.255.130.116]   File "/usr/local/lib/python2.7/dist-packages/django/views/debug.py", line 69, in technical_500_response
[Wed Sep 18 23:55:53 2013] [error] [client 193.255.130.116]     html = reporter.get_traceback_html()
[Wed Sep 18 23:55:53 2013] [error] [client 193.255.130.116]   File "/usr/local/lib/python2.7/dist-packages/django/views/debug.py", line 298, in get_traceback_html
[Wed Sep 18 23:55:53 2013] [error] [client 193.255.130.116]     return t.render(c)
[Wed Sep 18 23:55:53 2013] [error] [client 193.255.130.116]   File "/usr/local/lib/python2.7/dist-packages/django/template/base.py", line 140, in render
[Wed Sep 18 23:55:53 2013] [error] [client 193.255.130.116]     return self._render(context)
[Wed Sep 18 23:55:53 2013] [error] [client 193.255.130.116]   File "/usr/local/lib/python2.7/dist-packages/django/template/base.py", line 134, in _render
[Wed Sep 18 23:55:53 2013] [error] [client 193.255.130.116]     return self.nodelist.render(context)
[Wed Sep 18 23:55:53 2013] [error] [client 193.255.130.116]   File "/usr/local/lib/python2.7/dist-packages/django/template/base.py", line 830, in render
[Wed Sep 18 23:55:53 2013] [error] [client 193.255.130.116]     bit = self.render_node(node, context)
[Wed Sep 18 23:55:53 2013] [error] [client 193.255.130.116]   File "/usr/local/lib/python2.7/dist-packages/django/template/debug.py", line 74, in render_node
[Wed Sep 18 23:55:53 2013] [error] [client 193.255.130.116]     return node.render(context)
[Wed Sep 18 23:55:53 2013] [error] [client 193.255.130.116]   File "/usr/local/lib/python2.7/dist-packages/django/template/defaulttags.py", line 285, in render
[Wed Sep 18 23:55:53 2013] [error] [client 193.255.130.116]     return nodelist.render(context)
[Wed Sep 18 23:55:53 2013] [error] [client 193.255.130.116]   File "/usr/local/lib/python2.7/dist-packages/django/template/base.py", line 830, in render
[Wed Sep 18 23:55:53 2013] [error] [client 193.255.130.116]     bit = self.render_node(node, context)
[Wed Sep 18 23:55:53 2013] [error] [client 193.255.130.116]   File "/usr/local/lib/python2.7/dist-packages/django/template/debug.py", line 74, in render_node
[Wed Sep 18 23:55:53 2013] [error] [client 193.255.130.116]     return node.render(context)
[Wed Sep 18 23:55:53 2013] [error] [client 193.255.130.116]   File "/usr/local/lib/python2.7/dist-packages/django/template/debug.py", line 84, in render
[Wed Sep 18 23:55:53 2013] [error] [client 193.255.130.116]     output = self.filter_expression.resolve(context)
[Wed Sep 18 23:55:53 2013] [error] [client 193.255.130.116]   File "/usr/local/lib/python2.7/dist-packages/django/template/base.py", line 578, in resolve
[Wed Sep 18 23:55:53 2013] [error] [client 193.255.130.116]     obj = self.var.resolve(context)
[Wed Sep 18 23:55:53 2013] [error] [client 193.255.130.116]   File "/usr/local/lib/python2.7/dist-packages/django/template/base.py", line 728, in resolve
[Wed Sep 18 23:55:53 2013] [error] [client 193.255.130.116]     value = self._resolve_lookup(context)
[Wed Sep 18 23:55:53 2013] [error] [client 193.255.130.116]   File "/usr/local/lib/python2.7/dist-packages/django/template/base.py", line 779, in _resolve_lookup
[Wed Sep 18 23:55:53 2013] [error] [client 193.255.130.116]     current = current()
[Wed Sep 18 23:55:53 2013] [error] [client 193.255.130.116]   File "/usr/local/lib/python2.7/dist-packages/django/http/request.py", line 112, in build_absolute_uri
[Wed Sep 18 23:55:53 2013] [error] [client 193.255.130.116]     self.get_host(), self.path)
[Wed Sep 18 23:55:53 2013] [error] [client 193.255.130.116]   File "/usr/local/lib/python2.7/dist-packages/django/http/request.py", line 72, in get_host
[Wed Sep 18 23:55:53 2013] [error] [client 193.255.130.116]     "Invalid HTTP_HOST header (you may need to set ALLOWED_HOSTS): %s" % host)
[Wed Sep 18 23:55:53 2013] [error] [client 193.255.130.116] SuspiciousOperation: Invalid HTTP_HOST header (you may need to set ALLOWED_HOSTS): [HOST]
[Mon Sep 23 05:12:39 2013] [error] [client 176.34.99.194] client sent HTTP/1.1 request without hostname (see RFC2616 section 14.23): /w00tw00t.at.ISC.SANS.DFind:)
[Tue Sep 24 20:50:18 2013] [error] [client 89.248.171.13] client sent HTTP/1.1 request without hostname (see RFC2616 section 14.23): /w00tw00t.at.ISC.SANS.Win32:)
[Wed Sep 25 07:37:19 2013] [error] [client 89.248.171.13] client sent HTTP/1.1 request without hostname (see RFC2616 section 14.23): /w00tw00t.at.ISC.SANS.Win32:)
[Wed Sep 25 17:45:27 2013] [error] [client 89.248.171.13] client sent HTTP/1.1 request without hostname (see RFC2616 section 14.23): /w00tw00t.at.ISC.SANS.Win32:)
[Wed Sep 25 19:53:01 2013] [error] [client 62.141.44.237] client sent HTTP/1.1 request without hostname (see RFC2616 section 14.23): /w00tw00t.at.ISC.SANS.DFind:)
[Thu Sep 26 03:34:12 2013] [error] [client 89.248.171.13] client sent HTTP/1.1 request without hostname (see RFC2616 section 14.23): /w00tw00t.at.ISC.SANS.Win32:)
[Thu Sep 26 13:40:35 2013] [error] [client 89.248.171.13] client sent HTTP/1.1 request without hostname (see RFC2616 section 14.23): /w00tw00t.at.ISC.SANS.Win32:)
